Workbook

Sheet Все требования
E1: Выполнено в 1 релизе? | L1: Оценка на 28.09.2026 | M1: Статический анализ архива 23.09.2026. Стенд не проверен. H — план; L — оценка. | N1: Пути относительно корня архива. Полные основания: DKB_RELEASE_1_REVIEW_2026-09-28.md
B2: № требования | C2: Требование | D2: Задача в Jira | E2: На 05.08 | F2: На 04.09 | G2: На 07.09 | H2: Будет готово к проверке в релиз 1.0 | I2: Плановая дата реализации | J2: Комментарий | K2: Актуальный номер | L2: Оценка по архиву | M2: Замечания и необходимые подтверждения | N2: Основание: файл и строки
B3: Требования к реализации ролевой модели
B4: ДКБ-РМ-01 | C4: Ролевая модель должна соответствовать принципу наименьших привилегий. Выдаваться должны только те права и полномочия в системе, которые необходимы для выполнения конкретной задачи. (требование к ПУЗ выдаваемый через PAM, ТУЗ) | D4: https://jira.sberbank.ru/browse/CRPLTFRM-37124 | E4: =IF(EXACT(IFERROR(VLOOKUP(B4,' Первый релиз (05.08)'!$A$1:$A$96,1,FALSE),"нет"),B4),"Да","Нет") -> Да | F4: =IF(EXACT(IFERROR(VLOOKUP(B4,'Первый релиз (04.09)'!$A$1:$A$96,1,FALSE),"нет"),B4),"Да","Нет") -> Да | G4: Да | H4: Да | K4: 1 | L4: Частично | M4: Есть роли и назначения AD-групп. Минимум полномочий ПУЗ/ТУЗ требует проверки эффективных политик, включая OpenSearch all_access. | N4: ansible/roles/keystone/tasks/register.yml:62–70 ansible/roles/keystone/tasks/assign_ldap_roles.yml:47–68
B5: ДКБ-РМ-02 | C5: Не должно быть совмещения ролей администратора ПВ с любыми другими ролями, наследование и агрегирование прав должны быть согласованы с УЭК. | D5: https://jira.sberbank.ru/browse/CRPLTFRM-37124 | E5: =IF(EXACT(IFERROR(VLOOKUP(B5,' Первый релиз (05.08)'!$A$1:$A$96,1,FALSE),"нет"),B5),"Да","Нет") -> Да | F5: =IF(EXACT(IFERROR(VLOOKUP(B5,'Первый релиз (04.09)'!$A$1:$A$96,1,FALSE),"нет"),B5),"Да","Нет") -> Нет | G5: Да | H5: Да | J5: Обратить внимание на матрицу несовместимости ролей | K5: 2 | L5: Не подтверждено | M5: Автоматический запрет совмещения ролей не установлен. Нужны матрица несовместимости и отрицательная проверка назначения. | N5: ansible/roles/keystone/tasks/register.yml:62–70 ansible/roles/keystone/tasks/assign_ldap_roles.yml:47–68
B6: ДКБ-РМ-03 | C6: Запуск любых скриптов администраторами должен производиться только через PAM под привилегированной учетной записью. (ЦКЗ) | D6: https://jira.sberbank.ru/browse/CRPLTFRM-37124 | E6: =IF(EXACT(IFERROR(VLOOKUP(B6,' Первый релиз (05.08)'!$A$1:$A$96,1,FALSE),"нет"),B6),"Да","Нет") -> Нет | F6: =IF(EXACT(IFERROR(VLOOKUP(B6,'Первый релиз (04.09)'!$A$1:$A$96,1,FALSE),"нет"),B6),"Да","Нет") -> Нет | G6: Нет | K6: 5 | L6: Вне объёма оценки | M6: В колонке H нет отметки «Да» для релиза 1.0. Выполнение по архиву в этой оценке не анализировалось. | N6: Исходный Excel, «Все требования», H6
B7: ДКБ-РМ-04 | C7: Управление ролевыми моделями и ПУЗ, ТУЗ должны происходить в АС СУУПТ. | D7: https://jira.sberbank.ru/browse/CRPLTFRM-37124 | E7: =IF(EXACT(IFERROR(VLOOKUP(B7,' Первый релиз (05.08)'!$A$1:$A$96,1,FALSE),"нет"),B7),"Да","Нет") -> Нет | F7: =IF(EXACT(IFERROR(VLOOKUP(B7,'Первый релиз (04.09)'!$A$1:$A$96,1,FALSE),"нет"),B7),"Да","Нет") -> Нет | G7: Нет | K7: 6 | L7: Вне объёма оценки | M7: В колонке H нет отметки «Да» для релиза 1.0. Выполнение по архиву в этой оценке не анализировалось. | N7: Исходный Excel, «Все требования», H7
B8: ДКБ-РМ-05 | C8: Использование локальных технологических учетных записей для исполнения задач пользователей и администраторов запрещено. (ЦКЗ) | D8: https://jira.sberbank.ru/browse/CRPLTFRM-37124 | E8: =IF(EXACT(IFERROR(VLOOKUP(B8,' Первый релиз (05.08)'!$A$1:$A$96,1,FALSE),"нет"),B8),"Да","Нет") -> Нет | F8: =IF(EXACT(IFERROR(VLOOKUP(B8,'Первый релиз (04.09)'!$A$1:$A$96,1,FALSE),"нет"),B8),"Да","Нет") -> Да | G8: Да | H8: Да | K8: - | L8: Не подтверждено | M8: Технические УЗ создаются. Запрет их использования человеком для пользовательских и административных задач не подтверждён. | N8: ansible/roles/keystone/tasks/register.yml:2–13 ansible/roles/opensearch/defaults/main.yml:343–370
B9: ДКБ-РМ-06 | C9: Запрет использования локальных учетных записей в системе. | D9: https://jira.sberbank.ru/browse/CRPLTFRM-37124 | E9: =IF(EXACT(IFERROR(VLOOKUP(B9,' Первый релиз (05.08)'!$A$1:$A$96,1,FALSE),"нет"),B9),"Да","Нет") -> Да | F9: =IF(EXACT(IFERROR(VLOOKUP(B9,'Первый релиз (04.09)'!$A$1:$A$96,1,FALSE),"нет"),B9),"Да","Нет") -> Да | G9: Да | H9: Да | K9: 7* | L9: Разрыв | M9: В типовой конфигурации остаются локальный bootstrap-admin и внутренние УЗ OpenSearch. Зафиксировать допустимые исключения и запрет локального пользовательского входа. | N9: ansible/roles/keystone/tasks/register.yml:2–13 ansible/roles/opensearch/defaults/main.yml:343–370
B10: ДКБ-РМ-07 | C10: Учетные записи по умолчанию должны быть отключены | D10: https://jira.sberbank.ru/browse/CRPLTFRM-37124 | E10: =IF(EXACT(IFERROR(VLOOKUP(B10,' Первый релиз (05.08)'!$A$1:$A$96,1,FALSE),"нет"),B10),"Да","Нет") -> Да | F10: =IF(EXACT(IFERROR(VLOOKUP(B10,'Первый релиз (04.09)'!$A$1:$A$96,1,FALSE),"нет"),B10),"Да","Нет") -> Да | G10: Да | H10: Да | K10: 8 | L10: Не подтверждено | M10: Общее отключение стандартных УЗ не установлено. Проверить итоговый перечень УЗ и отключённые входы после развёртывания. | N10: ansible/roles/keystone/tasks/register.yml:2–13 ansible/roles/opensearch/defaults/main.yml:343–370
B11: ДКБ-РМ-08 | C11: UI пользователя (администратора) системы не должен отображать элементы, на работу с которыми у него нет прав. | D11: https://jira.sberbank.ru/browse/CRPLTFRM-37124 | E11: =IF(EXACT(IFERROR(VLOOKUP(B11,' Первый релиз (05.08)'!$A$1:$A$96,1,FALSE),"нет"),B11),"Да","Нет") -> Да | F11: =IF(EXACT(IFERROR(VLOOKUP(B11,'Первый релиз (04.09)'!$A$1:$A$96,1,FALSE),"нет"),B11),"Да","Нет") -> Нет | G11: Нет | J11: Элементы есть, но действия заблокированы | K11: 12 | L11: Вне объёма оценки | M11: В колонке H нет отметки «Да» для релиза 1.0. Выполнение по архиву в этой оценке не анализировалось. | N11: Исходный Excel, «Все требования», H11
B12: ДКБ-РМ-09 | C12: Парольная информация (ключи, секреты, пароли и т.д) должна храниться в Secman. | D12: https://jira.sberbank.ru/browse/CRPLTFRM-37124 | E12: =IF(EXACT(IFERROR(VLOOKUP(B12,' Первый релиз (05.08)'!$A$1:$A$96,1,FALSE),"нет"),B12),"Да","Нет") -> Да | F12: =IF(EXACT(IFERROR(VLOOKUP(B12,'Первый релиз (04.09)'!$A$1:$A$96,1,FALSE),"нет"),B12),"Да","Нет") -> Нет | G12: Да | H12: Да | J12: За исключением нулевых секретов (ДКБ-ЗСО-01) | K12: 63* | L12: Частично | M12: Есть SecMan-адаптер и ссылки на секреты. Проверить все потребители и постоянные копии. Исключение нулевых секретов из J12 сохранено. | N12: kolla_ansible/secret_backends.py:26–57 ansible/group_vars/all.yml:1807–1813
B13: ДКБ-РМ-10 | C13: Должна быть исключена доступ к паролям и другим конфиденциальным данным пользователей системы. | D13: https://jira.sberbank.ru/browse/CRPLTFRM-37124 | E13: =IF(EXACT(IFERROR(VLOOKUP(B13,' Первый релиз (05.08)'!$A$1:$A$96,1,FALSE),"нет"),B13),"Да","Нет") -> Нет | F13: =IF(EXACT(IFERROR(VLOOKUP(B13,'Первый релиз (04.09)'!$A$1:$A$96,1,FALSE),"нет"),B13),"Да","Нет") -> Нет | G13: Нет | K13: 13 | L13: Вне объёма оценки | M13: В колонке H нет отметки «Да» для релиза 1.0. Выполнение по архиву в этой оценке не анализировалось. | N13: Исходный Excel, «Все требования», H13
B14: ДКБ-РМ-11 | C14: Должен обеспечиваться контроль данных загружаемых в систему, исключающий возможность загрузки произвольного кода и исполняемых файлов (такие как SQL инъекции, скрипты, файлы запуска и т.д.). | D14: https://jira.sberbank.ru/browse/CRPLTFRM-37124 | E14: =IF(EXACT(IFERROR(VLOOKUP(B14,' Первый релиз (05.08)'!$A$1:$A$96,1,FALSE),"нет"),B14),"Да","Нет") -> Нет | F14: =IF(EXACT(IFERROR(VLOOKUP(B14,'Первый релиз (04.09)'!$A$1:$A$96,1,FALSE),"нет"),B14),"Да","Нет") -> Нет | G14: Нет | K14: 14 | L14: Вне объёма оценки | M14: В колонке H нет отметки «Да» для релиза 1.0. Выполнение по архиву в этой оценке не анализировалось. | N14: Исходный Excel, «Все требования», H14
B15: ДКБ-РМ-12 | C15: В средстве виртуализации должен быть реализован ролевой метод управления доступом с четырьмя ролями пользователей: разработчик виртуальной машины, администратор безопасности средства виртуализации, администратор средства виртуализации, администратор виртуальной машины. | D15: https://jira.sberbank.ru/browse/CRPLTFRM-37124 | E15: =IF(EXACT(IFERROR(VLOOKUP(B15,' Первый релиз (05.08)'!$A$1:$A$96,1,FALSE),"нет"),B15),"Да","Нет") -> Да | F15: =IF(EXACT(IFERROR(VLOOKUP(B15,'Первый релиз (04.09)'!$A$1:$A$96,1,FALSE),"нет"),B15),"Да","Нет") -> Нет | G15: Да | H15: Да | J15: Итоговая РМ будет учтена в следующем релизе | K15: 113 | L15: Частично; конфликт объёма | M15: Есть назначения member/admin. Четыре прикладные роли не подтверждены. H15=Да, но J15 переносит итоговую РМ в следующий релиз. | N15: ansible/roles/keystone/tasks/register.yml:62–70 ansible/roles/keystone/tasks/assign_ldap_roles.yml:47–68
B16: ДКБ-РМ-13 | C16: Роль разработчика виртуальной машины должна позволять: - создавать виртуальные машины; - изменять конфигурации виртуальных машин. | D16: https://jira.sberbank.ru/browse/CRPLTFRM-37124 | E16: =IF(EXACT(IFERROR(VLOOKUP(B16,' Первый релиз (05.08)'!$A$1:$A$96,1,FALSE),"нет"),B16),"Да","Нет") -> Да | F16: =IF(EXACT(IFERROR(VLOOKUP(B16,'Первый релиз (04.09)'!$A$1:$A$96,1,FALSE),"нет"),B16),"Да","Нет") -> Нет | G16: Да | H16: Да | K16: 114 | L16: Есть механизм | M16: AD-группа разработчиков получает member. Проверить создание и изменение конфигурации ВМ в разрешённом проекте. | N16: ansible/roles/keystone/tasks/register.yml:62–70 ansible/roles/keystone/tasks/assign_ldap_roles.yml:47–68
B17: ДКБ-РМ-14 | C17: Роль администратора безопасности средства виртуализации должна позволять: - иметь доступ на чтение к журналу событий безопасности средства виртуализации; - формировать отчеты с учетом заданных критериев отбора, выгрузку (экспорт) данных из журнала событий безопасности средства виртуализации. | D17: https://jira.sberbank.ru/browse/CRPLTFRM-37124 | E17: =IF(EXACT(IFERROR(VLOOKUP(B17,' Первый релиз (05.08)'!$A$1:$A$96,1,FALSE),"нет"),B17),"Да","Нет") -> Да | F17: =IF(EXACT(IFERROR(VLOOKUP(B17,'Первый релиз (04.09)'!$A$1:$A$96,1,FALSE),"нет"),B17),"Да","Нет") -> Нет | G17: Да | H17: Да | K17: 115 | L17: Частично | M17: Есть роль чтения и Dashboards. Проверить отчёты/экспорт под целевой ролью. LDAP-группа администратора OpenSearch получает all_access. | N17: ansible/roles/opensearch/defaults/main.yml:407–424, 457–467
B18: ДКБ-РМ-15 | C18: Роль администратора средства виртуализации должна позволять: - создавать учетные записи пользователей средства виртуализации; - управлять учетными записями пользователей средства виртуализации; - назначать права доступа пользователям средства виртуализации к виртуальным машинам; - создавать и удалять виртуальное оборудование средства виртуализации; - изменять конфигурации виртуального оборудования средства виртуализации; - управлять доступом виртуальных машин к физическому и виртуальному оборудованию; - управлять квотами доступа виртуальных машин к физическому и виртуальному оборудованию; - управлять перемещением виртуальных машин; - удалять виртуальные машины; - запускать и останавливать виртуальные машины; - создавать снимки состояния виртуальных машин, включающих файл конфигурации виртуальной машины, образа виртуальной машины и образа памяти виртуальной машины. | D18: https://jira.sberbank.ru/browse/CRPLTFRM-37124 | E18: =IF(EXACT(IFERROR(VLOOKUP(B18,' Первый релиз (05.08)'!$A$1:$A$96,1,FALSE),"нет"),B18),"Да","Нет") -> Да | F18: =IF(EXACT(IFERROR(VLOOKUP(B18,'Первый релиз (04.09)'!$A$1:$A$96,1,FALSE),"нет"),B18),"Да","Нет") -> Нет | G18: Да | H18: Да | K18: 116 | L18: Частично | M18: Есть admin, но полный перечень операций не испытан. Отдельно подтвердить снимок с конфигурацией, диском и памятью ВМ. | N18: ansible/roles/keystone/tasks/register.yml:62–70 ansible/roles/keystone/tasks/assign_ldap_roles.yml:47–68
B19: ДКБ-РМ-16 | C19: Роль администратора виртуальной машины должна позволять осуществлять доступ пользователя средства виртуализации к виртуальной машине посредством интерфейса средства виртуализации. | D19: https://jira.sberbank.ru/browse/CRPLTFRM-37124 | E19: =IF(EXACT(IFERROR(VLOOKUP(B19,' Первый релиз (05.08)'!$A$1:$A$96,1,FALSE),"нет"),B19),"Да","Нет") -> Нет | F19: =IF(EXACT(IFERROR(VLOOKUP(B19,'Первый релиз (04.09)'!$A$1:$A$96,1,FALSE),"нет"),B19),"Да","Нет") -> Нет | G19: Нет | K19: 117 | L19: Вне объёма оценки | M19: В колонке H нет отметки «Да» для релиза 1.0. Выполнение по архиву в этой оценке не анализировалось. | N19: Исходный Excel, «Все требования», H19
B20: Требования к механизмам аутентификации и авторизации
B21: ДКБ-А-01 | C21: Аутентификация с использованием привилегированных УЗ на компонентах ПВ должна осуществляться через АС PAM. | D21: https://jira.sberbank.ru/browse/CRPLTFRM-37124 | E21: =IF(EXACT(IFERROR(VLOOKUP(B21,' Первый релиз (05.08)'!$A$1:$A$96,1,FALSE),"нет"),B21),"Да","Нет") -> Нет | F21: =IF(EXACT(IFERROR(VLOOKUP(B21,'Первый релиз (04.09)'!$A$1:$A$96,1,FALSE),"нет"),B21),"Да","Нет") -> Да | G21: Да | H21: Да | J21: Подключение к инсталляции обязательно через PAM, требования в адрес СБТ не передается | K21: 16 | L21: Требование к окружению | M21: J21 относит доступ через PAM к окружению банка без передачи требования СБТ. Нужен протокол обязательного маршрута через PAM. | N21: Исходный Excel; отдельные документы и протоколы не представлены
B22: ДКБ-А-02 | C22: У администратора не должно быть прямого доступ к файловому хранилищу дисков виртуальных машин через административный интерфейс PV Stack | D22: https://jira.sberbank.ru/browse/CRPLTFRM-37124 | E22: =IF(EXACT(IFERROR(VLOOKUP(B22,' Первый релиз (05.08)'!$A$1:$A$96,1,FALSE),"нет"),B22),"Да","Нет") -> Да | F22: =IF(EXACT(IFERROR(VLOOKUP(B22,'Первый релиз (04.09)'!$A$1:$A$96,1,FALSE),"нет"),B22),"Да","Нет") -> Да | G22: Да | H22: Да | K22: 18 | L22: Не подтверждено | M22: Запрет прямого доступа к файловому хранилищу дисков через административный UI требует испытания готового интерфейса и его роли. | N22: ansible/roles/horizon/templates/_9998-kolla-settings.py.j2 ansible/roles/keystone/templates/keystone-ldap-domain.conf.j2
B23: ДКБ-А-03 | C23: Механизм резервного копирования PV Stack должен исключить необходимость предоставления привилегированного доступа к системе для администратора | D23: https://jira.sberbank.ru/browse/CRPLTFRM-37124 | E23: =IF(EXACT(IFERROR(VLOOKUP(B23,' Первый релиз (05.08)'!$A$1:$A$96,1,FALSE),"нет"),B23),"Да","Нет") -> Нет | F23: =IF(EXACT(IFERROR(VLOOKUP(B23,'Первый релиз (04.09)'!$A$1:$A$96,1,FALSE),"нет"),B23),"Да","Нет") -> Да | G23: ??? | J23: См. кейс с Крепостью | K23: 20 | L23: Вне объёма оценки | M23: В колонке H нет отметки «Да» для релиза 1.0. Выполнение по архиву в этой оценке не анализировалось. | N23: Исходный Excel, «Все требования», H23
B24: ДКБ-А-04 | C24: Должно быть реализовано ограничение количества неуспешных попыток доступа к ПВ с последующей блокировкой учетной записи доступа после достижения установленного максимального числа попыток. | D24: https://jira.sberbank.ru/browse/CRPLTFRM-37124 | E24: =IF(EXACT(IFERROR(VLOOKUP(B24,' Первый релиз (05.08)'!$A$1:$A$96,1,FALSE),"нет"),B24),"Да","Нет") -> Да | F24: =IF(EXACT(IFERROR(VLOOKUP(B24,'Первый релиз (04.09)'!$A$1:$A$96,1,FALSE),"нет"),B24),"Да","Нет") -> Да | G24: Да | H24: Да | K24: 21 | L24: Не подтверждено | M24: Проверить предел неуспешных попыток и блокировку УЗ в AD/Keystone/UI. Наличие LDAP само по себе ограничение не доказывает. | N24: ansible/roles/horizon/templates/_9998-kolla-settings.py.j2 ansible/roles/keystone/templates/keystone-ldap-domain.conf.j2
B25: ДКБ-А-05 | C25: Должно быть реализовано ограничение числа параллельных сеансов доступа. | D25: https://jira.sberbank.ru/browse/CRPLTFRM-37124 | E25: =IF(EXACT(IFERROR(VLOOKUP(B25,' Первый релиз (05.08)'!$A$1:$A$96,1,FALSE),"нет"),B25),"Да","Нет") -> Да | F25: =IF(EXACT(IFERROR(VLOOKUP(B25,'Первый релиз (04.09)'!$A$1:$A$96,1,FALSE),"нет"),B25),"Да","Нет") -> Да | G25: Да | H25: Да | K25: 22 | L25: Не подтверждено | M25: Явная настройка предела параллельных сеансов в шаблонах не найдена. Проверить готовый UI и все разрешённые способы входа. | N25: ansible/roles/horizon/templates/_9998-kolla-settings.py.j2 ansible/roles/keystone/templates/keystone-ldap-domain.conf.j2
B26: ДКБ-А-06 | C26: Блокирование сеанса доступа пользователя при неактивности, по истечении 15 минут. | D26: https://jira.sberbank.ru/browse/CRPLTFRM-37124 | E26: =IF(EXACT(IFERROR(VLOOKUP(B26,' Первый релиз (05.08)'!$A$1:$A$96,1,FALSE),"нет"),B26),"Да","Нет") -> Да | F26: =IF(EXACT(IFERROR(VLOOKUP(B26,'Первый релиз (04.09)'!$A$1:$A$96,1,FALSE),"нет"),B26),"Да","Нет") -> Да | G26: Да | H26: Да | K26: 23 | L26: Не подтверждено | M26: Явный тайм-аут бездействия 15 минут в шаблонах не найден. Нужен тест готового UI; это не доказательство отсутствия функции в образе. | N26: ansible/roles/horizon/templates/_9998-kolla-settings.py.j2 ansible/roles/keystone/templates/keystone-ldap-domain.conf.j2
B27: ДКБ-А-07 | C27: Первичная идентификация пользователей средства виртуализации 6 класса защиты должна осуществляться администратором средства виртуализации. | D27: https://jira.sberbank.ru/browse/CRPLTFRM-37124 | E27: =IF(EXACT(IFERROR(VLOOKUP(B27,' Первый релиз (05.08)'!$A$1:$A$96,1,FALSE),"нет"),B27),"Да","Нет") -> Нет | F27: =IF(EXACT(IFERROR(VLOOKUP(B27,'Первый релиз (04.09)'!$A$1:$A$96,1,FALSE),"нет"),B27),"Да","Нет") -> Да | G27: ??? | J27: Требование не к продукту vs. мнение коллег из отдела КИ | K27: 118 | L27: Вне объёма оценки | M27: В колонке H нет отметки «Да» для релиза 1.0. Выполнение по архиву в этой оценке не анализировалось. | N27: Исходный Excel, «Все требования», H27
B28: ДКБ-А-08 | C28: Идентификация и аутентификация пользователей в средстве виртуализации осуществляется с учетом требований разделов 4 – 7 ГОСТ Р 58833–2020 "Защита информации. Идентификация и аутентификация. Общие положения" | D28: https://jira.sberbank.ru/browse/CRPLTFRM-37124 | E28: =IF(EXACT(IFERROR(VLOOKUP(B28,' Первый релиз (05.08)'!$A$1:$A$96,1,FALSE),"нет"),B28),"Да","Нет") -> Нет | F28: =IF(EXACT(IFERROR(VLOOKUP(B28,'Первый релиз (04.09)'!$A$1:$A$96,1,FALSE),"нет"),B28),"Да","Нет") -> Да | G28: Да | H28: Да | K28: 119 | L28: Не подтверждено | M28: Нужно отдельное сопоставление и протокол по разделам 4–7 ГОСТ Р 58833–2020. По наличию AD соответствие не устанавливается. | N28: Исходный Excel; отдельные документы и протоколы не представлены
B29: ДКБ-А-09 | C29: Средство виртуализации должно осуществлять аутентификацию пользователей при предъявлении идентификатора и пароля пользователя. | D29: https://jira.sberbank.ru/browse/CRPLTFRM-37124 | E29: =IF(EXACT(IFERROR(VLOOKUP(B29,' Первый релиз (05.08)'!$A$1:$A$96,1,FALSE),"нет"),B29),"Да","Нет") -> Да | F29: =IF(EXACT(IFERROR(VLOOKUP(B29,'Первый релиз (04.09)'!$A$1:$A$96,1,FALSE),"нет"),B29),"Да","Нет") -> Нет | G29: Да | H29: Да | K29: 120 | L29: Есть механизм | M29: Keystone/LDAP и настройки Horizon предусматривают вход по учётным данным. Проверить целевой UI и домен. | N29: ansible/roles/horizon/templates/_9998-kolla-settings.py.j2 ansible/roles/keystone/templates/keystone-ldap-domain.conf.j2
B30: ДКБ-А-10 | C30: Пароль пользователя для первичной аутентификации должен устанавливаться администратором средства виртуализации. | D30: https://jira.sberbank.ru/browse/CRPLTFRM-37124 | E30: =IF(EXACT(IFERROR(VLOOKUP(B30,' Первый релиз (05.08)'!$A$1:$A$96,1,FALSE),"нет"),B30),"Да","Нет") -> Нет | F30: =IF(EXACT(IFERROR(VLOOKUP(B30,'Первый релиз (04.09)'!$A$1:$A$96,1,FALSE),"нет"),B30),"Да","Нет") -> Нет | G30: Нет | K30: 121 | L30: Вне объёма оценки | M30: В колонке H нет отметки «Да» для релиза 1.0. Выполнение по архиву в этой оценке не анализировалось. | N30: Исходный Excel, «Все требования», H30
B31: ДКБ-А-11 | C31: Средство виртуализации должно обеспечивать возможность смены установленного администратором средства виртуализации пароля пользователя средства виртуализации после его первичной аутентификации. | D31: https://jira.sberbank.ru/browse/CRPLTFRM-37124 | E31: =IF(EXACT(IFERROR(VLOOKUP(B31,' Первый релиз (05.08)'!$A$1:$A$96,1,FALSE),"нет"),B31),"Да","Нет") -> Нет | F31: =IF(EXACT(IFERROR(VLOOKUP(B31,'Первый релиз (04.09)'!$A$1:$A$96,1,FALSE),"нет"),B31),"Да","Нет") -> Нет | G31: Нет | K31: 122 | L31: Вне объёма оценки | M31: В колонке H нет отметки «Да» для релиза 1.0. Выполнение по архиву в этой оценке не анализировалось. | N31: Исходный Excel, «Все требования», H31
B32: ДКБ-А-12 | C32: Средство виртуализации должно обеспечивать невозможность установления одинаковых идентификаторов и паролей для разных пользователей. | D32: https://jira.sberbank.ru/browse/CRPLTFRM-37124 | E32: =IF(EXACT(IFERROR(VLOOKUP(B32,' Первый релиз (05.08)'!$A$1:$A$96,1,FALSE),"нет"),B32),"Да","Нет") -> Нет | F32: =IF(EXACT(IFERROR(VLOOKUP(B32,'Первый релиз (04.09)'!$A$1:$A$96,1,FALSE),"нет"),B32),"Да","Нет") -> Нет | G32: Нет | K32: 123 | L32: Вне объёма оценки | M32: В колонке H нет отметки «Да» для релиза 1.0. Выполнение по архиву в этой оценке не анализировалось. | N32: Исходный Excel, «Все требования», H32
B33: ДКБ-А-13 | C33: При попытке ввода неправильного значения идентификатора или пароля пользователя должно выводиться сообщение с приглашением ввести правильный идентификатор и пароль еще раз. | D33: https://jira.sberbank.ru/browse/CRPLTFRM-37124 | E33: =IF(EXACT(IFERROR(VLOOKUP(B33,' Первый релиз (05.08)'!$A$1:$A$96,1,FALSE),"нет"),B33),"Да","Нет") -> Да | F33: =IF(EXACT(IFERROR(VLOOKUP(B33,'Первый релиз (04.09)'!$A$1:$A$96,1,FALSE),"нет"),B33),"Да","Нет") -> Нет | G33: Да | H33: Да | K33: 124 | L33: Не подтверждено | M33: Проверить текст сообщения и повторный ввод при неверных данных в готовом UI. Исходный код формы в Kolla-архиве не представлен. | N33: ansible/roles/horizon/templates/_9998-kolla-settings.py.j2 ansible/roles/keystone/templates/keystone-ldap-domain.conf.j2
B34: ДКБ-А-14 | C34: При исчерпании установленного максимального количества неуспешных попыток ввода неправильного пароля учетная запись пользователя средства виртуализации должна быть заблокирована с возможностью разблокировки администратором средства виртуализации или с возможностью автоматической разблокировки по истечении временного интервала, устанавливаемого администратором средства виртуализации. | D34: https://jira.sberbank.ru/browse/CRPLTFRM-37124 | E34: =IF(EXACT(IFERROR(VLOOKUP(B34,' Первый релиз (05.08)'!$A$1:$A$96,1,FALSE),"нет"),B34),"Да","Нет") -> Нет | F34: =IF(EXACT(IFERROR(VLOOKUP(B34,'Первый релиз (04.09)'!$A$1:$A$96,1,FALSE),"нет"),B34),"Да","Нет") -> Нет | G34: Нет | K34: 125 | L34: Вне объёма оценки | M34: В колонке H нет отметки «Да» для релиза 1.0. Выполнение по архиву в этой оценке не анализировалось. | N34: Исходный Excel, «Все требования», H34
B35: ДКБ-А-15 | C35: Защита пароля пользователя средства виртуализации должна обеспечиваться при его вводе за счет отображения вводимых символов условными знаками. | D35: https://jira.sberbank.ru/browse/CRPLTFRM-37124 | E35: =IF(EXACT(IFERROR(VLOOKUP(B35,' Первый релиз (05.08)'!$A$1:$A$96,1,FALSE),"нет"),B35),"Да","Нет") -> Да | F35: =IF(EXACT(IFERROR(VLOOKUP(B35,'Первый релиз (04.09)'!$A$1:$A$96,1,FALSE),"нет"),B35),"Да","Нет") -> Да | G35: Да | H35: Да | K35: 126 | L35: Не подтверждено | M35: Маскирование пароля при вводе проверить в готовом UI. Kolla-шаблоны не доказывают поведение поля ввода в образе. | N35: ansible/roles/horizon/templates/_9998-kolla-settings.py.j2 ansible/roles/keystone/templates/keystone-ldap-domain.conf.j2
B36: Требования к защите сетевых соединений
B37: ДКБ-С-01 | C37: Системы-участники (включая части системы, шлюзы, платформенные сервисы и т.д.) при сетевых взаимодействиях должны обеспечивать строгую аутентификацию и авторизацию друг друга с помощью криптостойких алгоритмов шифрования, соответствующих комплаенсу банка. Сетевые соединения с не аутентифицированными и/или неавторизованными сторонами должен быть исключен. | D37: https://jira.sberbank.ru/browse/CRPLTFRM-37124 | E37: =IF(EXACT(IFERROR(VLOOKUP(B37,' Первый релиз (05.08)'!$A$1:$A$96,1,FALSE),"нет"),B37),"Да","Нет") -> Да | F37: =IF(EXACT(IFERROR(VLOOKUP(B37,'Первый релиз (04.09)'!$A$1:$A$96,1,FALSE),"нет"),B37),"Да","Нет") -> Да | G37: Да | H37: Да | K37: 24 | L37: Частично; разрыв | M37: Есть mTLS для ряда каналов. OpenSearch HAProxy-backend использует ssl verify none. Общие TLS/mTLS-флаги выключены по умолчанию; проверить все потоки и авторизацию. | N37: ansible/roles/opensearch/defaults/main.yml:63 ansible/roles/haproxy-config/templates/haproxy_single_service_split.cfg.j2:92–111
B38: ДКБ-С-02 | C38: Сертификаты должны быть выпущены УЦ банка. Должен быть реализован механизм проверки их по спискам отзыва (OCSP/CRL) | D38: https://jira.sberbank.ru/browse/CRPLTFRM-37124 | E38: =IF(EXACT(IFERROR(VLOOKUP(B38,' Первый релиз (05.08)'!$A$1:$A$96,1,FALSE),"нет"),B38),"Да","Нет") -> Нет | F38: =IF(EXACT(IFERROR(VLOOKUP(B38,'Первый релиз (04.09)'!$A$1:$A$96,1,FALSE),"нет"),B38),"Да","Нет") -> Да | G38: ??? | J38: Вопрос к формулировке требования vs. Аутентификация по клиентскому сертификату | K38: 25 | L38: Вне объёма оценки | M38: В колонке H нет отметки «Да» для релиза 1.0. Выполнение по архиву в этой оценке не анализировалось. | N38: Исходный Excel, «Все требования», H38
B39: ДКБ-С-03 | C39: Поддержка возможности сетевой изоляции одной ВМ от другой в том числе в пределах одного сетевого сегмента. | D39: https://jira.sberbank.ru/browse/CRPLTFRM-37124 | E39: =IF(EXACT(IFERROR(VLOOKUP(B39,' Первый релиз (05.08)'!$A$1:$A$96,1,FALSE),"нет"),B39),"Да","Нет") -> Да | F39: =IF(EXACT(IFERROR(VLOOKUP(B39,'Первый релиз (04.09)'!$A$1:$A$96,1,FALSE),"нет"),B39),"Да","Нет") -> Да | G39: Да | H39: Да | K39: 29 | L39: Есть механизм | M39: Neutron Security Groups. Испытать изоляцию ВМ, включая две ВМ в одном сегменте и смену узла размещения. | N39: ansible/roles/neutron/templates/openvswitch_agent.ini.j2:13–14 ansible/roles/host-firewall/vars/catalog.yml
B40: ДКБ-С-04 | C40: Реализация возможности создать правило разграничения сетевого доступа для одного хоста. | D40: https://jira.sberbank.ru/browse/CRPLTFRM-37124 | E40: =IF(EXACT(IFERROR(VLOOKUP(B40,' Первый релиз (05.08)'!$A$1:$A$96,1,FALSE),"нет"),B40),"Да","Нет") -> Да | F40: =IF(EXACT(IFERROR(VLOOKUP(B40,'Первый релиз (04.09)'!$A$1:$A$96,1,FALSE),"нет"),B40),"Да","Нет") -> Да | G40: Да | H40: Да | K40: 31 | L40: Есть механизм | M40: Есть базовые фильтры ВМ и host firewall. Проверить создание правила для отдельного узла в согласованном контуре. | N40: ansible/roles/neutron/templates/openvswitch_agent.ini.j2:13–14 ansible/roles/host-firewall/vars/catalog.yml
...

Sheet Первый релиз (04.09)
A1: № требования | B1: Формулировка | C1: Реализовано/описание
A2: ДКБ-РМ-01 | B2: Ролевая модель должна соответствовать принципу наименьших привилегий. Выдаваться должны только те права и полномочия в системе, которые необходимы для выполнения конкретной задачи. (требование к ПУЗ выдаваемый через PAM, ТУЗ) | C2: Да
A3: ДКБ-РМ-05 | B3: Использование локальных технологических учетных записей для исполнения задач пользователей и администраторов запрещено. (ЦКЗ) | C3: Да (оставить ток учетки сервисов)
A4: ДКБ-РМ-06 | B4: Запрет использования локальных учетных записей в системе. | C4: Да - настроить учетки
A5: ДКБ-РМ-07 | B5: Учетные записи по умолчанию должны быть отключены | C5: Да - настроить учетки
A6: ДКБ-А-01 | B6: Аутентификация с использованием привилегированных УЗ на компонентах ПВ должна осуществляться через АС PAM. | C6: PAM - только в horizon
A7: ДКБ-А-02 | B7: У администратора не должно быть прямого доступ к файловому хранилищу дисков виртуальных машин через административный интерфейс PV Stack | C7: Да
A8: ДКБ-А-03 | B8: Механизм резервного копирования PV Stack должен исключить необходимость предоставления привилегированного доступа к системе для администратора | C8: Да (Не понятно о чем речь. РК можно создавать внутренним механизмом cinder-backup, а можно внешней СРК. Если речь про внутренний механизм, то подтверждаю)
A9: ДКБ-А-04 | B9: Должно быть реализовано ограничение количества неуспешных попыток доступа к ПВ с последующей блокировкой учетной записи доступа после достижения установленного максимального числа попыток. | C9: Да, horizone/keystone
A10: ДКБ-А-05 | B10: Должно быть реализовано ограничение числа параллельных сеансов доступа. | C10: Да, horizone
A11: ДКБ-А-06 | B11: Блокирование сеанса доступа пользователя при неактивности, по истечении 15 минут. | C11: Да, настройка horizon
A12: ДКБ-А-07 | B12: Первичная идентификация пользователей средства виртуализации 6 класса защиты должна осуществляться администратором средства виртуализации. | C12: ФСТЭК (но требование поддерживается)
... A48: ДКБ-SEC-01 | B48: Должна быть реализована возможность автоматизированной ротации артефактов авторизации (секреты, токены expiration, projected). | C48: secman

Sheet  Первый релиз (05.08)
A1: № требования | B1: Требование | C1: Проверка
A2: ДКБ-РМ-01 | B2: Ролевая модель должна соответствовать принципу наименьших привилегий. Выдаваться должны только те права и полномочия в системе, которые необходимы для выполнения конкретной задачи. (требование к ПУЗ выдаваемый через PAM, ТУЗ) | C2: =VLOOKUP(A2,'Все требования'!$B$2:$B$170,1,FALSE) -> ДКБ-РМ-01
A3: ДКБ-РМ-02 | B3: Не должно быть совмещения ролей администратора ПВ с любыми другими ролями, наследования и агрегирования прав должно быть согласовано с УЭК. | C3: =VLOOKUP(A3,'Все требования'!$B$2:$B$170,1,FALSE) -> ДКБ-РМ-02
A4: ДКБ-РМ-06 | B4: Запрет использования локальных учетных записей в системе. | C4: =VLOOKUP(A4,'Все требования'!$B$2:$B$170,1,FALSE) -> ДКБ-РМ-06
A5: ДКБ-РМ-07 | B5: Учетные записи по умолчанию должны быть отключены | C5: =VLOOKUP(A5,'Все требования'!$B$2:$B$170,1,FALSE) -> ДКБ-РМ-07
A6: ДКБ-РМ-08 | B6: UI пользователя (администратора) системы не должен отображать элементы, на работу с которыми у него нет прав. | C6: =VLOOKUP(A6,'Все требования'!$B$2:$B$170,1,FALSE) -> ДКБ-РМ-08
A7: ДКБ-РМ-09 | B7: Парольная информация (ключи, секреты, пароли и т.д) должна храниться в Secman. | C7: =VLOOKUP(A7,'Все требования'!$B$2:$B$170,1,FALSE) -> ДКБ-РМ-09
A8: ДКБ-РМ-12 | B8: В средстве виртуализации должен быть реализован ролевой метод управления доступом с четырьмя ролями пользователей: разработчик виртуальной машины, администратор безопасности средства виртуализации, администратор средства виртуализации, администратор виртуальной машины. | C8: =VLOOKUP(A8,'Все требования'!$B$2:$B$170,1,FALSE) -> ДКБ-РМ-12
A9: ДКБ-РМ-13 | B9: Роль разработчика виртуальной машины должна позволять: - создавать виртуальные машины; - изменять конфигурации виртуальных машин. | C9: =VLOOKUP(A9,'Все требования'!$B$2:$B$170,1,FALSE) -> ДКБ-РМ-13
A10: ДКБ-РМ-14 | B10: Роль администратора безопасности средства виртуализации должна позволять: - иметь доступ на чтение к журналу событий безопасности средства виртуализации; - формировать отчеты с учетом заданных критериев отбора, выгрузку (экспорт) данных из журнала событий безопасности средства виртуализации. | C10: =VLOOKUP(A10,'Все требования'!$B$2:$B$170,1,FALSE) -> ДКБ-РМ-14
A11: ДКБ-РМ-15 | B11: Роль администратора средства виртуализации должна позволять: - создавать учетные записи пользователей средства виртуализации; - управлять учетными записями пользователей средства виртуализации; - назначать права доступа пользователям средства виртуализации к виртуальным машинам; - создавать и удалять виртуальное оборудование средства виртуализации; - изменять конфигурации виртуального оборудования средства виртуализации; - управлять доступом виртуальных машин к физическому и виртуальному оборудованию; - управлять квотами доступа виртуальных машин к физическому и виртуальному оборудованию; - управлять перемещением виртуальных машин; - удалять виртуальные машины; - запускать и останавливать виртуальные машины; - создавать снимки состояния виртуальных машин, включающих файл конфигурации виртуальной машины, образа виртуальной машины и образа памяти виртуальной машины. | C11: =VLOOKUP(A11,'Все требования'!$B$2:$B$170,1,FALSE) -> ДКБ-РМ-15
A12: ДКБ-А-02 | B12: У администратора не должно быть прямого доступ к файловому хранилищу дисков виртуальных машин через административный интерфейс PV Stack | C12: =VLOOKUP(A12,'Все требования'!$B$2:$B$170,1,FALSE) -> ДКБ-А-02
A13: ДКБ-А-04 | B13: Должно быть реализовано ограничение количества неуспешных попыток доступа к ПВ с последующей блокировкой учетной записи доступа после достижения установленного максимального числа попыток. | C13: =VLOOKUP(A13,'Все требования'!$B$2:$B$170,1,FALSE) -> ДКБ-А-04
... A96: ДКБ-ИНТ-01 | B96: Использование любых API (портов) и интерфейсов, входящих в состав продукта, должны быть описаны. Неиспользуемые API и интерфейсы должны быть заблокированы. | C96: =VLOOKUP(A96,'Все требования'!$B$2:$B$170,1,FALSE) -> ДКБ-ИНТ-01

Sheet Первый релиз (07.09)
B2: № требования | C2: Требование | D2: Задача в Jira | E2: В 1 релизе? | F2: Комментарий
B3: ДКБ-РМ-01 | C3: Ролевая модель должна соответствовать принципу наименьших привилегий. Выдаваться должны только те права и полномочия в системе, которые необходимы для выполнения конкретной задачи. (требование к ПУЗ выдаваемый через PAM, ТУЗ) | D3: https://jira.sberbank.ru/browse/CRPLTFRM-37124 | E3: Да
B4: ДКБ-РМ-02 | C4: Не должно быть совмещения ролей администратора ПВ с любыми другими ролями, наследования и агрегирования прав должно быть согласовано с УЭК. | D4: https://jira.sberbank.ru/browse/CRPLTFRM-37124 | E4: ???
B5: ДКБ-РМ-03 | C5: Запуск любых скриптов администраторами должен производиться только через PAM под привилегированной учетной записью. (ЦКЗ) | D5: https://jira.sberbank.ru/browse/CRPLTFRM-37124 | E5: Нет
B6: ДКБ-РМ-04 | C6: Управление ролевыми моделями и ПУЗ, ТУЗ должны происходить в АС СУУПТ. | D6: https://jira.sberbank.ru/browse/CRPLTFRM-37124 | E6: Нет
B7: ДКБ-РМ-05 | C7: Использование локальных технологических учетных записей для исполнения задач пользователей и администраторов запрещено. (ЦКЗ) | D7: https://jira.sberbank.ru/browse/CRPLTFRM-37124 | E7: Да
B8: ДКБ-РМ-06 | C8: Запрет использования локальных учетных записей в системе. | D8: https://jira.sberbank.ru/browse/CRPLTFRM-37124 | E8: Да
B9: ДКБ-РМ-07 | C9: Учетные записи по умолчанию должны быть отключены | D9: https://jira.sberbank.ru/browse/CRPLTFRM-37124 | E9: Да
B10: ДКБ-РМ-08 | C10: UI пользователя (администратора) системы не должен отображать элементы, на работу с которыми у него нет прав. | D10: https://jira.sberbank.ru/browse/CRPLTFRM-37124 | E10: ??? | F10: Элементы есть, но действия заблокированы
B11: ДКБ-РМ-09 | C11: Парольная информация (ключи, секреты, пароли и т.д) должна храниться в Secman. | D11: https://jira.sberbank.ru/browse/CRPLTFRM-37124 | E11: Да | F11: За исключением нулевых секретов
B12: ДКБ-РМ-10 | C12: Должна быть исключена доступ к паролям и другим конфиденциальным данным пользователей системы. | D12: https://jira.sberbank.ru/browse/CRPLTFRM-37124 | E12: Нет
B13: ДКБ-РМ-11 | C13: Должен обеспечиваться контроль данных загружаемых в систему, исключающий возможность загрузки произвольного кода и исполняемых файлов (такие как SQL инъекции, скрипты, файлы запуска и т.д.). | D13: https://jira.sberbank.ru/browse/CRPLTFRM-37124 | E13: Нет
B14: ДКБ-РМ-12 | C14: В средстве виртуализации должен быть реализован ролевой метод управления доступом с четырьмя ролями пользователей: разработчик виртуальной машины, администратор безопасности средства виртуализации, администратор средства виртуализации, администратор виртуальной машины. | D14: https://jira.sberbank.ru/browse/CRPLTFRM-37124 | E14: Да | F14: Итоговая РМ будет учтена в следующем релизе
B15: ДКБ-РМ-13 | C15: Роль разработчика виртуальной машины должна позволять: создавать виртуальные машины; - изменять конфигурации виртуальных машин. | D15: https://jira.sberbank.ru/browse/CRPLTFRM-37124 | E15: Да
B16: ДКБ-РМ-14 | C16: Роль администратора безопасности средства виртуализации должна позволять:- иметь доступ на чтение к журналу событий безопасности средства виртуализации;- формировать отчеты с учетом заданных критериев отбора, выгрузку (экспорт) данных из журнала событий безопасности средства виртуализации. | D16: https://jira.sberbank.ru/browse/CRPLTFRM-37124 | E16: Да
B17: ДКБ-РМ-15 | C17: Роль администратора средства виртуализации должна позволять: - создавать учетные записи пользователей средства виртуализации; - управлять учетными записями пользователей средства виртуализации; - назначать права доступа пользователям средства виртуализации к виртуальным машинам; - создавать и удалять виртуальное оборудование средства виртуализации; - изменять конфигурации виртуального оборудования средства виртуализации; управлять доступом виртуальных машин к физическому и виртуальному оборудованию; - управлять квотами доступа виртуальных машин к физическому и виртуальному оборудованию; управлять перемещением виртуальных машин; - удалять виртуальные машины; запускать и останавливать виртуальные машины; - создавать снимки состояния виртуальных машин, включающих файл конфигурации виртуальной машины, образа виртуальной машины и образа памяти виртуальной машины. | D17: https://jira.sberbank.ru/browse/CRPLTFRM-37124 | E17: Да
B18: ДКБ-РМ-16 | C18: Роль администратора виртуальной машины должна позволять осуществлять доступ пользователя средства виртуализации к виртуальной машине посредством интерфейса средства виртуализации. | D18: https://jira.sberbank.ru/browse/CRPLTFRM-37124 | E18: Нет
B19: ДКБ-А-01 | C19: Аутентификация с использованием привилегированных УЗ на компонентах ПВ должна осуществляться через АС PAM. | D19: https://jira.sberbank.ru/browse/CRPLTFRM-37124 | E19: ??? | F19: Требование к инсталляции
B20: ДКБ-А-02 | C20: У администратора не должно быть прямого доступ к файловому хранилищу дисков виртуальных машин через административный интерфейс PV Stack | D20: https://jira.sberbank.ru/browse/CRPLTFRM-37124 | E20: Да
B21: ДКБ-А-03 | C21: Механизм резервного копирования PV Stack должен исключить необходимость предоставления привилегированного доступа к системе для администратора | D21: https://jira.sberbank.ru/browse/CRPLTFRM-37124 | E21: ???
B22: ДКБ-А-04 | C22: Должно быть реализовано ограничение количества неуспешных попыток доступа к ПВ с последующей блокировкой учетной записи доступа после достижения установленного максимального числа попыток. | D22: https://jira.sberbank.ru/browse/CRPLTFRM-37124 | E22: Да
B23: ДКБ-А-05 | C23: Должно быть реализовано ограничение числа параллельных сеансов доступа. | D23: https://jira.sberbank.ru/browse/CRPLTFRM-37124 | E23: Да
B24: ДКБ-А-06 | C24: Блокирование сеанса доступа пользователя при неактивности, по истечении 15 минут. | D24: https://jira.sberbank.ru/browse/CRPLTFRM-37124 | E24: Да
B25: ДКБ-А-07 | C25: Первичная идентификация пользователей средства виртуализации 6 класса защиты должна осуществляться администратором средства виртуализации. | D25: https://jira.sberbank.ru/browse/CRPLTFRM-37124 | E25: ??? | F25: Требование не к продукту
B26: ДКБ-А-08 | C26: Идентификация и аутентификация пользователей в средстве виртуализации осуществляется с учетом требований разделов 4 – 7 ГОСТ Р 58833–2020 "Защита информации. Идентификация и аутентификация. Общие положения" | D26: https://jira.sberbank.ru/browse/CRPLTFRM-37124 | E26: Да
B27: ДКБ-А-09 | C27: Средство виртуализации должно осуществлять аутентификацию пользователей при предъявлении идентификатора и пароля пользователя. | D27: https://jira.sberbank.ru/browse/CRPLTFRM-37124 | E27: Да
B28: ДКБ-А-10 | C28: Пароль пользователя для первичной аутентификации должен устанавливаться администратором средства виртуализации. | D28: https://jira.sberbank.ru/browse/CRPLTFRM-37124 | E28: Нет
B29: ДКБ-А-11 | C29: Средство виртуализации должно обеспечивать возможность смены установленного администратором средства виртуализации пароля пользователя средства виртуализации после его первичной аутентификации. | D29: https://jira.sberbank.ru/browse/CRPLTFRM-37124 | E29: Нет
B30: ДКБ-А-12 | C30: Средство виртуализации должно обеспечивать невозможность установления одинаковых идентификаторов и паролей для разных пользователей. | D30: https://jira.sberbank.ru/browse/CRPLTFRM-37124 | E30: Нет
B31: ДКБ-А-13 | C31: При попытке ввода неправильного значения идентификатора или пароля пользователя должно выводиться сообщение с приглашением ввести правильный идентификатор и пароль еще раз. | D31: https://jira.sberbank.ru/browse/CRPLTFRM-37124 | E31: Да
B32: ДКБ-А-14 | C32: При исчерпании установленного максимального количества неуспешных попыток ввода неправильного пароля учетная запись пользователя средства виртуализации должна быть заблокирована с возможностью разблокировки администратором средства виртуализации или с возможностью автоматической разблокировки по истечении временного интервала, устанавливаемого администратором средства виртуализации. | D32: https://jira.sberbank.ru/browse/CRPLTFRM-37124 | E32: Нет
B33: ДКБ-А-15 | C33: Защита пароля пользователя средства виртуализации должна обеспечиваться при его вводе за счет отображения вводимых символов условными знаками. | D33: https://jira.sberbank.ru/browse/CRPLTFRM-37124 | E33: Да
B34: ДКБ-С-01 | C34: Системы-участники (включая части системы, шлюзы, платформенные сервисы и т.д.) при сетевых взаимодействиях должны обеспечивать строгую аутентификацию и авторизацию друг друга с помощью криптостойких алгоритмов шифрования, соответствующих комплаенсу банка. Сетевые соединения с не аутентифицированными и/или неавторизованными сторонами должен быть исключен. | D34: https://jira.sberbank.ru/browse/CRPLTFRM-37124 | E34: Да
B35: ДКБ-С-02 | C35: Сертификаты должны быть выпущены УЦ банка. Должен быть реализован механизм проверки их по спискам отзыва (OCSP/CRL) | D35: https://jira.sberbank.ru/browse/CRPLTFRM-37124 | E35: ??? | F35: Вопрос к формулировке требования
B36: ДКБ-С-03 | C36: Поддержка возможности сетевой изоляции одной ВМ от другой в том числе в пределах одного сетевого сегмента. | D36: https://jira.sberbank.ru/browse/CRPLTFRM-37124 | E36: Да
B37: ДКБ-С-04 | C37: Реализация возможности создать правило разграничения сетевого доступа для одного хоста. | D37: https://jira.sberbank.ru/browse/CRPLTFRM-37124 | E37: Да
B38: ДКБ-С-05 | C38: Реализация возможности создать правило разграничения сетевого доступа для группы хостов. | D38: https://jira.sberbank.ru/browse/CRPLTFRM-37124 | E38: Да
B39: ДКБ-С-06 | C39: Реализация возможности создать правило разграничения сетевого доступа для одного хоста и конкретного сетевого интерфейса. | D39: https://jira.sberbank.ru/browse/CRPLTFRM-37124 | E39: Да
B40: ДКБ-С-07 | C40: Реализация возможности создать правило разграничения сетевого доступа для группы хостов и конкретных сетевых интерфейсов на них. | D40: https://jira.sberbank.ru/browse/CRPLTFRM-37124 | E40: Да
B41: ДКБ-С-08 | C41: Реализация возможности просмотра правила разграничения сетевого доступа для одного хоста. | D41: https://jira.sberbank.ru/browse/CRPLTFRM-37124 | E41: Да
...

Sheet Все требования (07.09)
B2: № П/П | C2: Требование | D2: Код исходного требования
B3: 1 | C3: Ролевая модель должна соответствовать принципу наименьших привилегий. Выдаваться должны только те права и полномочия в системе, которые необходимы для выполнения конкретной задачи | D3: ДКБ-РМ-01
B4: 2 | C4: Не должно быть совмещения ролей администратора ПВ с любыми другими ролями, наследования и агрегирования прав должно быть согласовано с ДКБ. | D4: ДКБ-РМ-02
B5: 3 | C5: Любой доступ, включая доступ к данным, а также его актуализация, должен осуществляться на основании ролевых моделей. | D5: -
B6: 4 | C6: Не должно быть совмещения ролей администратора ПВ с любыми другими ролями. | D6: Дубль требования 2
B7: 5 | C7: Запуск любых скриптов администраторами должен производиться только через PAM под привилегированной учетной записью. | D7: ДКБ-РМ-03
B8: 6 | C8: Управление ролевыми моделями и ПУЗ, ТУЗ должны происходить в АС СУУПТ. | D8: ДКБ-РМ-04
B9: 7 | C9: Запрет использования локальных учетных записей в системе. Исключения должны быть явно согласованы с ДКБ. | D9: ДКБ-РМ-06*
B10: 8 | C10: Учетные записи по умолчанию должны быть отключены | D10: ДКБ-РМ-07
B11: 9 | C11: Сервисы Openstack контроллеров undercloud/deployer должны иметь ролевую модель отличную от хостовой ОС. Для ролевой модели должна быть разработана матрица доступа и должна соответствовать принципу несовместимости ролей. Должен соблюдаться принцип минимизации полномочий. | D11: -
B12: 10 | C12: Не допускается использование локальной ролевой модели. | D12: -
B13: 11 | C13: Ролевая модель администратора по умолчанию должна быть выключена. | D13: -
B14: 12 | C14: UI пользователя (администратора) системы не должен отображать элементы, на работу с которыми у него нет прав. | D14: ДКБ-РМ-08
... B153: 151 | C153: Пароль пользователя средства виртуализации должен содержать не менее 8 символов при алфавите пароля не менее 70 символов. Максимальное количество неуспешных попыток аутентификации (ввода неправильного пароля) до блокировки – 4 | D153: ДКБ-SEC-03
